<?xml version="1.0" encoding="utf-8"?>
<!-- =================================================================================== -->
<!-- |    This document was autogenerated by xacro from urdf/mesh_arm.xacro            | -->
<!-- |    EDITING THIS FILE BY HAND IS NOT RECOMMENDED                                 | -->
<!-- =================================================================================== -->
<robot name="seven_dof_arm_using_mesh">
  <material name="Black">
    <color rgba="0.5 0.5 0.5 1"/>
  </material>
  <material name="White">
    <color rgba="1 1 1 1"/>
  </material>
  <group name="mesh_arm">
    <chain base_link="base_link" tip_link="link_7"/>
  </group>
  <link name="base_link">
    <visual>
      <geometry>
        <mesh filename="package://robot_description_pkg/meshes/base_link.stl" scale="0.001 0.001 0.001"/>
      </geometry>
      <origin rpy="0 0 0" xyz="0 0 0"/>
      <material name="White"/>
    </visual>
    <collision>
      <geometry>
        <mesh filename="package://robot_description_pkg/meshes/base_link.stl" scale="0.0011 0.0011 0.0011"/>
      </geometry>
      <origin rpy="0 0 0" xyz="0 0 0"/>
    </collision>
  </link>
  <joint name="base_link-link_1" type="revolute">
    <parent link="base_link"/>
    <child link="link_1"/>
    <origin xyz="0 0 0.06"/>
    <axis xyz="0 0 1"/>
    <limit effort="300" lower="-3.14" upper="3.14" velocity="0.1"/>
  </joint>
  <link name="link_1">
    <visual>
      <geometry>
        <mesh filename="package://robot_description_pkg/meshes/link_1.stl" scale="0.001 0.001 0.001"/>
      </geometry>
      <origin rpy="0 0 0" xyz="0 0 0"/>
      <material name="Black"/>
    </visual>
    <collision>
      <geometry>
        <mesh filename="package://robot_description_pkg/meshes/link_1.stl" scale="0.0011 0.0011 0.0011"/>
      </geometry>
      <origin rpy="0 0 0" xyz="0 0 0"/>
    </collision>
    <inertial>
      <mass value="0.5"/>
      <inertia ixx="160347952.0" ixy="0.073988" ixz="15663199.0" iyy="149014144.0" iyz="0.506316" izz="44131488.0"/>
    </inertial>
  </link>
  <joint name="link_1-link_2" type="revolute">
    <parent link="link_1"/>
    <child link="link_2"/>
    <origin xyz="0 0 0.08"/>
    <axis xyz="1 0 0"/>
    <limit effort="300" lower="-1.57" upper="1.57" velocity="0.1"/>
  </joint>
  <link name="link_2">
    <visual>
      <geometry>
        <mesh filename="package://robot_description_pkg/meshes/link_2.stl" scale="0.001 0.001 0.001"/>
      </geometry>
      <origin rpy="0 0 0" xyz="0 0 0"/>
      <material name="White"/>
    </visual>
    <collision>
      <geometry>
        <mesh filename="package://robot_description_pkg/meshes/link_2.stl" scale="0.0011 0.0011 0.0011"/>
      </geometry>
      <origin rpy="0 0 0" xyz="0 0 0"/>
    </collision>
    <inertial>
      <mass value="0.5"/>
      <inertia ixx="320315008.0" ixy="0.025285" ixz="1.992257" iyy="295672384.0" iyz="0.10713" izz="42775932.0"/>
    </inertial>
  </link>
  <joint name="link_2-link_3" type="revolute">
    <parent link="link_2"/>
    <child link="link_3"/>
    <origin xyz="0 0 0.1"/>
    <axis xyz="1 0 0"/>
    <limit effort="300" lower="-1.57" upper="1.57" velocity="0.1"/>
  </joint>
  <link name="link_3">
    <visual>
      <geometry>
        <mesh filename="package://robot_description_pkg/meshes/link_3.stl" scale="0.001 0.001 0.001"/>
      </geometry>
      <origin rpy="0 0 0" xyz="0 0 0"/>
      <material name="Black"/>
    </visual>
    <collision>
      <geometry>
        <mesh filename="package://robot_description_pkg/meshes/link_3.stl" scale="0.0011 0.0011 0.0011"/>
      </geometry>
      <origin rpy="0 0 0" xyz="0 0 0"/>
    </collision>
    <inertial>
      <mass value="0.5"/>
      <inertia ixx="93527256.0" ixy="0.003871" ixz="12514371.0" iyy="87003976.0" iyz="0.035148" izz="40058448.0"/>
    </inertial>
  </link>
  <joint name="link_3-link_4" type="revolute">
    <parent link="link_3"/>
    <child link="link_4"/>
    <origin xyz="0 0 0.06"/>
    <axis xyz="0 0 1"/>
    <limit effort="300" lower="-1.57" upper="1.57" velocity="0.1"/>
  </joint>
  <link name="link_4">
    <visual>
      <geometry>
        <mesh filename="package://robot_description_pkg/meshes/link_4.stl" scale="0.001 0.001 0.001"/>
      </geometry>
      <origin rpy="0 0 0" xyz="0 0 0"/>
      <material name="White"/>
    </visual>
    <collision>
      <geometry>
        <mesh filename="package://robot_description_pkg/meshes/link_4.stl" scale="0.0011 0.0011 0.0011"/>
      </geometry>
      <origin rpy="0 0 0" xyz="0 0 0"/>
    </collision>
    <inertial>
      <mass value="0.5"/>
      <inertia ixx="93527256.0" ixy="0.003871" ixz="12514371.0" iyy="87003976.0" iyz="0.035148" izz="40058448.0"/>
    </inertial>
  </link>
  <joint name="link_4-link_5" type="revolute">
    <parent link="link_4"/>
    <child link="link_5"/>
    <origin xyz="0 0 0.06"/>
    <axis xyz="1 0 0"/>
    <limit effort="300" lower="-1.57" upper="1.57" velocity="0.1"/>
  </joint>
  <link name="link_5">
    <visual>
      <geometry>
        <mesh filename="package://robot_description_pkg/meshes/link_3.stl" scale="0.001 0.001 0.001"/>
      </geometry>
      <origin rpy="0 0 3.14" xyz="0 0 0"/>
      <material name="Black"/>
    </visual>
    <collision>
      <geometry>
        <mesh filename="package://robot_description_pkg/meshes/link_3.stl" scale="0.0011 0.0011 0.0011"/>
      </geometry>
      <origin rpy="0 0 3.14" xyz="0 0 0"/>
    </collision>
    <inertial>
      <mass value="0.5"/>
      <inertia ixx="93527256.0" ixy="0.003871" ixz="12514371.0" iyy="87003976.0" iyz="0.035148" izz="40058448.0"/>
    </inertial>
  </link>
  <joint name="link_5-link_6" type="revolute">
    <parent link="link_5"/>
    <child link="link_6"/>
    <origin xyz="0 0 0.06"/>
    <axis xyz="0 0 1"/>
    <limit effort="300" lower="-1.57" upper="1.57" velocity="0.1"/>
  </joint>
  <link name="link_6">
    <visual>
      <geometry>
        <mesh filename="package://robot_description_pkg/meshes/link_4.stl" scale="0.001 0.001 0.001"/>
      </geometry>
      <origin rpy="0 0 3.14" xyz="0 0 0"/>
      <material name="White"/>
    </visual>
    <collision>
      <geometry>
        <mesh filename="package://robot_description_pkg/meshes/link_4.stl" scale="0.0011 0.0011 0.0011"/>
      </geometry>
      <origin rpy="0 0 3.14" xyz="0 0 0"/>
    </collision>
    <inertial>
      <mass value="0.5"/>
      <inertia ixx="93527256.0" ixy="0.003871" ixz="12514371.0" iyy="87003976.0" iyz="0.035148" izz="40058448.0"/>
    </inertial>
  </link>
  <joint name="link_6-link_7" type="revolute">
    <parent link="link_6"/>
    <child link="link_7"/>
    <origin xyz="0 0 0.06"/>
    <axis xyz="1 0 0"/>
    <limit effort="300" lower="-1.57" upper="1.57" velocity="0.1"/>
  </joint>
  <link name="link_7">
    <visual>
      <geometry>
        <mesh filename="package://robot_description_pkg/meshes/link_5.stl" scale="0.001 0.001 0.001"/>
      </geometry>
      <origin rpy="0 0 0" xyz="0 0 0"/>
      <material name="Black"/>
    </visual>
    <collision>
      <geometry>
        <mesh filename="package://robot_description_pkg/meshes/link_5.stl" scale="0.0011 0.0011 0.0011"/>
      </geometry>
      <origin rpy="0 0 0" xyz="0 0 0"/>
    </collision>
    <inertial>
      <mass value="0.5"/>
      <inertia ixx="130744760.0" ixy="0.001162" ixz="20542782.0" iyy="127046656.0" iyz="0.004876" izz="49867952.0"/>
    </inertial>
  </link>
</robot>

