<?xml version="1.0" encoding="utf-8"?>
<!-- =================================================================================== -->
<!-- |    This document was autogenerated by xacro from urdf/mesh_arm.xacro            | -->
<!-- |    EDITING THIS FILE BY HAND IS NOT RECOMMENDED                                 | -->
<!-- =================================================================================== -->
<robot name="seven_dof_arm_using_mesh">
  <material name="Black">
    <color rgba="0.5 0.5 0.5 1"/>
  </material>
  <material name="White">
    <color rgba="1 1 1 1"/>
  </material>
  <group name="arm_group">
    <chain base_link="base_link" tip_link="link_7"/>
  </group>
  <group name="hand_group">
    <link name="hand"/>
    <link name="finger_1"/>
    <link name="finger_2"/>
    <joint name="hand-finger"/>
    <passive_joint name="hand-finger_2"/>
  </group>
  <disable_collision link1="base_link" link2="link_1" reason="Adjacent"/>
  <disable_collision link1="link_1" link2="link_2" reason="Adjacent"/>
  <disable_collision link1="link_2" link2="link_3" reason="Adjacent"/>
  <disable_collision link1="link_3" link2="link_4" reason="Adjacent"/>
  <disable_collision link1="link_4" link2="link_5" reason="Adjacent"/>
  <disable_collision link1="link_5" link2="link_6" reason="Adjacent"/>
  <disable_collision link1="link_6" link2="link_7" reason="Adjacent"/>
  <disable_collision link1="base_link" link2="link_2" reason="Never"/>
  <disable_collision link1="base_link" link2="link_3" reason="Never"/>
  <disable_collision link1="link_1" link2="link_3" reason="Never"/>
  <disable_collision link1="link_1" link2="link_4" reason="Never"/>
  <disable_collision link1="link_1" link2="link_5" reason="Never"/>
  <disable_collision link1="link_2" link2="link_4" reason="Never"/>
  <disable_collision link1="link_2" link2="link_5" reason="Never"/>
  <disable_collision link1="link_2" link2="link_6" reason="Never"/>
  <disable_collision link1="link_3" link2="link_5" reason="Never"/>
  <disable_collision link1="link_3" link2="link_6" reason="Never"/>
  <disable_collision link1="link_3" link2="link_7" reason="Never"/>
  <disable_collision link1="link_4" link2="link_6" reason="Never"/>
  <disable_collision link1="link_4" link2="link_7" reason="Never"/>
  <disable_collision link1="link_5" link2="link_7" reason="Never"/>
  <disable_collision link1="hand" link2="finger_1" reason="Adjacent"/>
  <disable_collision link1="hand" link2="finger_2" reason="Adjacent"/>
  <disable_collision link1="finger_1" link2="finger_2" reason="Fingers"/>
  <disable_collision link1="hand" link2="link_7" reason="Adjacent"/>
  <disable_collision link1="hand" link2="link_6" reason="Never"/>
  <disable_collision link1="hand" link2="link_5" reason="Never"/>
  <disable_collision link1="hand" link2="link_4" reason="Never"/>
  <disable_collision link1="hand" link2="link_3" reason="Never"/>
  <disable_collision link1="finger_1" link2="link_7" reason="Never"/>
  <disable_collision link1="finger_1" link2="link_6" reason="Never"/>
  <disable_collision link1="finger_1" link2="link_5" reason="Never"/>
  <disable_collision link1="finger_1" link2="link_4" reason="Never"/>
  <disable_collision link1="finger_1" link2="link_3" reason="Never"/>
  <disable_collision link1="finger_2" link2="link_7" reason="Never"/>
  <disable_collision link1="finger_2" link2="link_6" reason="Never"/>
  <disable_collision link1="finger_2" link2="link_5" reason="Never"/>
  <disable_collision link1="finger_2" link2="link_4" reason="Never"/>
  <disable_collision link1="finger_2" link2="link_3" reason="Never"/>
  <end_effector group="hand_group" name="hand" parent_group="arm_group" parent_link="link_7"/>
  <link name="base_link">
    <visual>
      <geometry>
        <mesh filename="package://robot_description_pkg/meshes/base_link.stl" scale="0.001 0.001 0.001"/>
      </geometry>
      <origin rpy="0 0 0" xyz="0 0 0"/>
      <material name="White"/>
    </visual>
    <collision>
      <geometry>
        <mesh filename="package://robot_description_pkg/meshes/base_link.stl" scale="0.0011 0.0011 0.0011"/>
      </geometry>
      <origin rpy="0 0 0" xyz="0 0 0"/>
    </collision>
  </link>
  <joint name="base_link-link_1" type="revolute">
    <parent link="base_link"/>
    <child link="link_1"/>
    <origin xyz="0 0 0.06"/>
    <axis xyz="0 0 1"/>
    <limit effort="300" lower="-3.14" upper="3.14" velocity="0.1"/>
  </joint>
  <link name="link_1">
    <visual>
      <geometry>
        <mesh filename="package://robot_description_pkg/meshes/link_1.stl" scale="0.001 0.001 0.001"/>
      </geometry>
      <origin rpy="0 0 0" xyz="0 0 0"/>
      <material name="Black"/>
    </visual>
    <collision>
      <geometry>
        <mesh filename="package://robot_description_pkg/meshes/link_1.stl" scale="0.0011 0.0011 0.0011"/>
      </geometry>
      <origin rpy="0 0 0" xyz="0 0 0"/>
    </collision>
    <inertial>
      <mass value="0.5"/>
      <inertia ixx="160347952.0" ixy="0.073988" ixz="15663199.0" iyy="149014144.0" iyz="0.506316" izz="44131488.0"/>
    </inertial>
  </link>
  <joint name="link_1-link_2" type="revolute">
    <parent link="link_1"/>
    <child link="link_2"/>
    <origin xyz="0 0 0.08"/>
    <axis xyz="1 0 0"/>
    <limit effort="300" lower="-2.3" upper="2.3" velocity="0.1"/>
  </joint>
  <link name="link_2">
    <visual>
      <geometry>
        <mesh filename="package://robot_description_pkg/meshes/link_2.stl" scale="0.001 0.001 0.001"/>
      </geometry>
      <origin rpy="0 0 0" xyz="0 0 0"/>
      <material name="White"/>
    </visual>
    <collision>
      <geometry>
        <mesh filename="package://robot_description_pkg/meshes/link_2.stl" scale="0.0011 0.0011 0.0011"/>
      </geometry>
      <origin rpy="0 0 0" xyz="0 0 0"/>
    </collision>
    <inertial>
      <mass value="0.5"/>
      <inertia ixx="320315008.0" ixy="0.025285" ixz="1.992257" iyy="295672384.0" iyz="0.10713" izz="42775932.0"/>
    </inertial>
  </link>
  <joint name="link_2-link_3" type="revolute">
    <parent link="link_2"/>
    <child link="link_3"/>
    <origin xyz="0 0 0.1"/>
    <axis xyz="1 0 0"/>
    <limit effort="300" lower="-1.8" upper="1.8" velocity="0.1"/>
  </joint>
  <link name="link_3">
    <visual>
      <geometry>
        <mesh filename="package://robot_description_pkg/meshes/link_3.stl" scale="0.001 0.001 0.001"/>
      </geometry>
      <origin rpy="0 0 0" xyz="0 0 0"/>
      <material name="Black"/>
    </visual>
    <collision>
      <geometry>
        <mesh filename="package://robot_description_pkg/meshes/link_3.stl" scale="0.0011 0.0011 0.0011"/>
      </geometry>
      <origin rpy="0 0 0" xyz="0 0 0"/>
    </collision>
    <inertial>
      <mass value="0.5"/>
      <inertia ixx="93527256.0" ixy="0.003871" ixz="12514371.0" iyy="87003976.0" iyz="0.035148" izz="40058448.0"/>
    </inertial>
  </link>
  <joint name="link_3-link_4" type="revolute">
    <parent link="link_3"/>
    <child link="link_4"/>
    <origin xyz="0 0 0.06"/>
    <axis xyz="0 0 1"/>
    <limit effort="300" lower="-3.14" upper="3.14" velocity="0.1"/>
  </joint>
  <link name="link_4">
    <visual>
      <geometry>
        <mesh filename="package://robot_description_pkg/meshes/link_4.stl" scale="0.001 0.001 0.001"/>
      </geometry>
      <origin rpy="0 0 0" xyz="0 0 0"/>
      <material name="White"/>
    </visual>
    <collision>
      <geometry>
        <mesh filename="package://robot_description_pkg/meshes/link_4.stl" scale="0.0011 0.0011 0.0011"/>
      </geometry>
      <origin rpy="0 0 0" xyz="0 0 0"/>
    </collision>
    <inertial>
      <mass value="0.5"/>
      <inertia ixx="93527256.0" ixy="0.003871" ixz="12514371.0" iyy="87003976.0" iyz="0.035148" izz="40058448.0"/>
    </inertial>
  </link>
  <joint name="link_4-link_5" type="revolute">
    <parent link="link_4"/>
    <child link="link_5"/>
    <origin xyz="0 0 0.06"/>
    <axis xyz="1 0 0"/>
    <limit effort="300" lower="-1.8" upper="1.8" velocity="0.1"/>
  </joint>
  <link name="link_5">
    <visual>
      <geometry>
        <mesh filename="package://robot_description_pkg/meshes/link_3.stl" scale="0.001 0.001 0.001"/>
      </geometry>
      <origin rpy="0 0 3.14" xyz="0 0 0"/>
      <material name="Black"/>
    </visual>
    <collision>
      <geometry>
        <mesh filename="package://robot_description_pkg/meshes/link_3.stl" scale="0.0011 0.0011 0.0011"/>
      </geometry>
      <origin rpy="0 0 3.14" xyz="0 0 0"/>
    </collision>
    <inertial>
      <mass value="0.5"/>
      <inertia ixx="93527256.0" ixy="0.003871" ixz="12514371.0" iyy="87003976.0" iyz="0.035148" izz="40058448.0"/>
    </inertial>
  </link>
  <joint name="link_5-link_6" type="revolute">
    <parent link="link_5"/>
    <child link="link_6"/>
    <origin xyz="0 0 0.06"/>
    <axis xyz="0 0 1"/>
    <limit effort="300" lower="-3.14" upper="3.14" velocity="0.1"/>
  </joint>
  <link name="link_6">
    <visual>
      <geometry>
        <mesh filename="package://robot_description_pkg/meshes/link_4.stl" scale="0.001 0.001 0.001"/>
      </geometry>
      <origin rpy="0 0 3.14" xyz="0 0 0"/>
      <material name="White"/>
    </visual>
    <collision>
      <geometry>
        <mesh filename="package://robot_description_pkg/meshes/link_4.stl" scale="0.0011 0.0011 0.0011"/>
      </geometry>
      <origin rpy="0 0 3.14" xyz="0 0 0"/>
    </collision>
    <inertial>
      <mass value="0.5"/>
      <inertia ixx="93527256.0" ixy="0.003871" ixz="12514371.0" iyy="87003976.0" iyz="0.035148" izz="40058448.0"/>
    </inertial>
  </link>
  <joint name="link_6-link_7" type="revolute">
    <parent link="link_6"/>
    <child link="link_7"/>
    <origin xyz="0 0 0.06"/>
    <axis xyz="1 0 0"/>
    <limit effort="300" lower="-1.8" upper="1.8" velocity="0.1"/>
  </joint>
  <link name="link_7">
    <visual>
      <geometry>
        <mesh filename="package://robot_description_pkg/meshes/link_5.stl" scale="0.001 0.001 0.001"/>
      </geometry>
      <origin rpy="0 0 0" xyz="0 0 0"/>
      <material name="Black"/>
    </visual>
    <collision>
      <geometry>
        <mesh filename="package://robot_description_pkg/meshes/link_5.stl" scale="0.0011 0.0011 0.0011"/>
      </geometry>
      <origin rpy="0 0 0" xyz="0 0 0"/>
    </collision>
    <inertial>
      <mass value="0.5"/>
      <inertia ixx="130744760.0" ixy="0.001162" ixz="20542782.0" iyy="127046656.0" iyz="0.004876" izz="49867952.0"/>
    </inertial>
  </link>
  <joint name="link_7-hand" type="fixed">
    <parent link="link_7"/>
    <child link="hand"/>
    <origin xyz="0 0 0.085"/>
  </joint>
  <link name="hand">
    <visual>
      <geometry>
        <mesh filename="package://robot_description_pkg/meshes/hand.stl" scale="0.001 0.001 0.001"/>
      </geometry>
      <origin rpy="0 0 0" xyz="0 0 0"/>
      <material name="White"/>
    </visual>
    <collision>
      <geometry>
        <mesh filename="package://robot_description_pkg/meshes/hand.stl" scale="0.0011 0.0011 0.0011"/>
      </geometry>
      <origin rpy="0 0 0" xyz="0 0 0"/>
    </collision>
    <inertial>
      <mass value="0.5"/>
      <inertia ixx="13535881.0" ixy="0.005851" ixz="0.209502" iyy="48692132.0" iyz="0.001552" izz="42968752.0"/>
    </inertial>
  </link>
  <joint name="hand-finger" type="prismatic">
    <parent link="hand"/>
    <child link="finger_1"/>
    <origin xyz="0.03 0 0.04"/>
    <limit effort="100" lower="0" upper="-0.03" velocity="1.0"/>
  </joint>
  <link name="finger_1">
    <visual>
      <geometry>
        <mesh filename="package://robot_description_pkg/meshes/finger.stl" scale="0.001 0.001 0.001"/>
      </geometry>
      <origin rpy="0 0 0" xyz="0 0 0"/>
      <material name="Black"/>
    </visual>
    <collision>
      <geometry>
        <mesh filename="package://robot_description_pkg/meshes/finger.stl" scale="0.0011 0.0011 0.0011"/>
      </geometry>
      <origin rpy="0 0 0" xyz="0 0 0"/>
    </collision>
    <inertial>
      <mass value="0.25"/>
      <inertia ixx="1640625.0" ixy="0.000262" ixz="416666.65625" iyy="1453125.5" iyz="0.000365" izz="593749.9375"/>
    </inertial>
  </link>
  <joint name="hand-finger_2" type="prismatic">
    <parent link="hand"/>
    <child link="finger_2"/>
    <origin xyz="-0.03 0 0.04"/>
    <limit effort="100" lower="0" upper="0.03" velocity="1.0"/>
    <mimic joint="hand-finger" multiplier="-1"/>
  </joint>
  <link name="finger_2">
    <visual>
      <geometry>
        <mesh filename="package://robot_description_pkg/meshes/finger.stl" scale="0.001 0.001 0.001"/>
      </geometry>
      <origin rpy="0 0 3.14" xyz="0 0 0"/>
      <material name="Black"/>
    </visual>
    <collision>
      <geometry>
        <mesh filename="package://robot_description_pkg/meshes/finger.stl" scale="0.0011 0.0011 0.0011"/>
      </geometry>
      <origin rpy="0 0 3.14" xyz="0 0 0"/>
    </collision>
    <inertial>
      <mass value="0.25"/>
      <inertia ixx="1640625.0" ixy="0.000262" ixz="416666.65625" iyy="1453125.5" iyz="0.000365" izz="593749.9375"/>
    </inertial>
  </link>
</robot>

