<?xml version="1.0"?>
<robot name="seven_dof_arm_using_mesh" xmlns:xacro="http://www.ros.org/wiki/xacro" >

  <material name="Black">
    <color rgba="0.5 0.5 0.5 1"/>
  </material>

  <material name="White">
    <color rgba="1 1 1 1"/>
  </material>

  <xacro:include filename="$(find robot_description_pkg)/urdf/mesh_arm_grouping.xacro"/>
  <xacro:group_arm/>

  <xacro:property name="base_link_mesh" value="package://robot_description_pkg/meshes/base_link.stl"/>
  <xacro:property name="link_1_mesh" value="package://robot_description_pkg/meshes/link_1.stl"/>
  <xacro:property name="link_2_mesh" value="package://robot_description_pkg/meshes/link_2.stl"/>
  <xacro:property name="link_3_mesh" value="package://robot_description_pkg/meshes/link_3.stl"/>
  <xacro:property name="link_4_mesh" value="package://robot_description_pkg/meshes/link_4.stl"/>
  <xacro:property name="link_5_mesh" value="package://robot_description_pkg/meshes/link_3.stl"/>
  <xacro:property name="link_6_mesh" value="package://robot_description_pkg/meshes/link_4.stl"/>
  <xacro:property name="link_7_mesh" value="package://robot_description_pkg/meshes/link_5.stl"/>
  <xacro:property name="hand_mesh" value="package://robot_description_pkg/meshes/hand.stl"/>
  <xacro:property name="finger_mesh" value="package://robot_description_pkg/meshes/finger.stl"/>

  <xacro:macro name="make_link" params="name mesh xyz rpy color mass ixx ixy ixz iyy iyz izz">
    <link name="${name}">
      <visual>
        <geometry>
          <mesh filename="${mesh}" scale="0.001 0.001 0.001"/>
        </geometry>
        <origin xyz="${xyz}" rpy="${rpy}"/>
        <material name="${color}"/>
      </visual>
      <collision>
        <geometry>
          <mesh filename="${mesh}" scale="0.0011 0.0011 0.0011"/>
        </geometry>
        <origin xyz="${xyz}" rpy="${rpy}"/>
      </collision>
      <inertial>
        <mass value="${mass}"/>
        <inertia ixx="${ixx}" ixy="${ixy}" ixz="${ixz}" iyy="${iyy}" iyz="${iyz}" izz="${izz}"/>
      </inertial>
    </link>
  </xacro:macro>

  <xacro:macro name="join_links" params="name parent child xyz axis lower upper">
    <joint name="${name}" type="revolute">
      <parent link="${parent}"/>
      <child link="${child}"/>
      <origin xyz="${xyz}"/>
      <axis xyz="${axis}"/>
      <limit effort="300" velocity="0.1" lower="${lower}" upper="${upper}"/>
    </joint>
  </xacro:macro>

  <xacro:macro name="fix_links" params="name parent child xyz">
    <joint name="${name}" type="fixed">
      <parent link="${parent}"/>
      <child link="${child}"/>
      <origin xyz="${xyz}"/>
    </joint>
  </xacro:macro>

  <link name="base_link">
    <visual>
      <geometry>
        <mesh filename="${base_link_mesh}" scale="0.001 0.001 0.001"/>
      </geometry>
      <origin xyz="0 0 0" rpy="0 0 0"/>
      <material name="White"/>
    </visual>
    <collision>
      <geometry>
        <mesh filename="${base_link_mesh}" scale="0.0011 0.0011 0.0011"/>
      </geometry>
      <origin xyz="0 0 0" rpy="0 0 0"/>
    </collision>
  </link>

  <xacro:join_links name="base_link-link_1"
    parent="base_link"
    child="link_1"
    xyz="0 0 0.06"
    axis="0 0 1"
    lower="-3.14"
    upper="3.14"/>

  <xacro:make_link name="link_1"
    mesh="${link_1_mesh}"
    xyz="0 0 0"
    rpy="0 0 0"
    color="Black"
    mass="0.5"
    ixx="160347952.000000" ixy="0.073988" ixz="15663199.000000"
    iyy="149014144.000000" iyz="0.506316"
    izz="44131488.000000"/>

  <xacro:join_links name="link_1-link_2"
    parent="link_1"
    child="link_2"
    xyz="0 0 0.08"
    axis="1 0 0"
    lower="-1.57"
    upper="1.57"/>

  <xacro:make_link name="link_2"
    mesh="${link_2_mesh}"
    xyz="0 0 0"
    rpy="0 0 0"
    color="White"
    mass="0.5"
    ixx="320315008.000000" ixy="0.025285" ixz="1.992257"
    iyy="295672384.000000" iyz="0.107130"
    izz="42775932.000000"/>

  <xacro:join_links name="link_2-link_3"
    parent="link_2"
    child="link_3"
    xyz="0 0 0.1"
    axis="1 0 0"
    lower="-1.57"
    upper="1.57"/>

  <xacro:make_link name="link_3"
    mesh="${link_3_mesh}"
    xyz="0 0 0"
    rpy="0 0 0"
    color="Black"
    mass="0.5"
    ixx="93527256.000000" ixy="0.003871" ixz="12514371.000000"
    iyy="87003976.000000" iyz="0.035148"
    izz="40058448.000000"/>

  <xacro:join_links name="link_3-link_4"
    parent="link_3"
    child="link_4"
    xyz="0 0 0.06"
    axis="0 0 1"
    lower="-1.57"
    upper="1.57"/>

  <xacro:make_link name="link_4"
    mesh="${link_4_mesh}"
    xyz="0 0 0"
    rpy="0 0 0"
    color="White"
    mass="0.5"
    ixx="93527256.000000" ixy="0.003871" ixz="12514371.000000"
    iyy="87003976.000000" iyz="0.035148"
    izz="40058448.000000"/>

  <xacro:join_links name="link_4-link_5"
    parent="link_4"
    child="link_5"
    xyz="0 0 0.06"
    axis="1 0 0"
    lower="-1.57"
    upper="1.57"/>

  <xacro:make_link name="link_5"
    mesh="${link_5_mesh}"
    xyz="0 0 0"
    rpy="0 0 3.14"
    color="Black"
    mass="0.5"
    ixx="93527256.000000" ixy="0.003871" ixz="12514371.000000"
    iyy="87003976.000000" iyz="0.035148"
    izz="40058448.000000"/>

  <xacro:join_links name="link_5-link_6"
    parent="link_5"
    child="link_6"
    xyz="0 0 0.06"
    axis="0 0 1"
    lower="-1.57"
    upper="1.57"/>

  <xacro:make_link name="link_6"
    mesh="${link_6_mesh}"
    xyz="0 0 0"
    rpy="0 0 3.14"
    color="White"
    mass="0.5"
    ixx="93527256.000000" ixy="0.003871" ixz="12514371.000000"
    iyy="87003976.000000" iyz="0.035148"
    izz="40058448.000000"/>

  <xacro:join_links name="link_6-link_7"
    parent="link_6"
    child="link_7"
    xyz="0 0 0.06"
    axis="1 0 0"
    lower="-1.57"
    upper="1.57"/>

  <xacro:make_link name="link_7"
    mesh="${link_7_mesh}"
    xyz="0 0 0"
    rpy="0 0 0"
    color="Black"
    mass="0.5"
    ixx="130744760.000000" ixy="0.001162" ixz="20542782.000000"
    iyy="127046656.000000" iyz="0.004876"
    izz="49867952.000000"/>

  <xacro:fix_links name="link_7-hand"
    parent="link_7"
    child="hand"
    xyz="0 0 0.085"/>

  <xacro:make_link name="hand"
    mesh="${hand_mesh}"
    xyz="0 0 0"
    rpy="0 0 0"
    color="White"
    mass="0.5"
    ixx="13535881.000000" ixy="0.005851" ixz="0.209502"
    iyy="48692132.000000" iyz="0.001552"
    izz="42968752.000000"/>

  <joint name="hand-finger" type="prismatic">
    <parent link="hand"/>
    <child link="finger_1"/>
    <origin xyz="0.03 0 0.04"/>
    <limit effort="100" velocity="1.0" lower="0" upper="-0.03"/>
  </joint>

  <xacro:make_link name="finger_1"
    mesh="${finger_mesh}"
    xyz="0 0 0"
    rpy="0 0 0"
    color="Black"
    mass="0.25"
    ixx="1640625.000000" ixy="0.000262" ixz="416666.656250"
    iyy="1453125.500000" iyz="0.000365"
    izz="593749.937500"/>

  <joint name="hand-finger_2" type="prismatic">
    <parent link="hand"/>
    <child link="finger_2"/>
    <origin xyz="-0.03 0 0.04"/>
    <limit effort="100" velocity="1.0" lower="0" upper="0.03"/>
    <mimic joint="hand-finger" multiplier="-1"/>
  </joint>

  <xacro:make_link name="finger_2"
    mesh="${finger_mesh}"
    xyz="0 0 0"
    rpy="0 0 3.14"
    color="Black"
    mass="0.25"
    ixx="1640625.000000" ixy="0.000262" ixz="416666.656250"
    iyy="1453125.500000" iyz="0.000365"
    izz="593749.937500"/>

</robot>
