<?xml version="1.0" encoding="utf-8"?>
<!-- =================================================================================== -->
<!-- |    This document was autogenerated by xacro from urdf/panda_based_arm.xacro     | -->
<!-- |    EDITING THIS FILE BY HAND IS NOT RECOMMENDED                                 | -->
<!-- =================================================================================== -->
<robot name="panda_based_arm">
  <material name="Black">
    <color rgba="0 0 0 1"/>
  </material>
  <material name="White">
    <color rgba="1 1 1 1"/>
  </material>
  <link name="origin">
      <origin xyz="0 0 0.005"/>
  </link>
  <joint name="rotating_base" type="revolute">
    <parent link="origin"/>
    <child link="base_link"/>
    <origin xyz="0 0 0"/>
    <axis xyz="0 0 1"/>
    <limit effort="300" lower="-3.14" upper="3.14" velocity="0.1"/>
  </joint>
  <link name="base_link">
    <visual>
      <geometry>
        <box size="0.4 0.4 0.01"/>
      </geometry>
      <origin xyz="0 0 0.005"/>
    </visual>
  </link>
  <joint name="base-link_1" type="revolute">
    <parent link="base_link"/>
    <child link="link_1"/>
    <origin xyz="0 0 0.01"/>
    <axis xyz="0 0 1"/>
    <limit effort="300" lower="-3.14" upper="3.14" velocity="0.1"/>
  </joint>
  <link name="link_1">
    <visual>
      <geometry>
        <cylinder length="0.1" radius="0.05"/>
      </geometry>
      <origin xyz="0 0 0.05"/>
    </visual>
  </link>
  <joint name="link_1-link_2" type="fixed">
    <parent link="link_1"/>
    <child link="link_2"/>
    <origin xyz="0 0 0.1"/>
  </joint>
  <link name="link_2">
    <visual>
      <geometry>
        <box size="0.025 0.025 0.1"/>
      </geometry>
      <origin rpy="0 0 0" xyz="0 0 0.05"/>
      <material name="Black"/>
    </visual>
  </link>
  <joint name="link_2-link_3" type="revolute">
    <parent link="link_2"/>
    <child link="link_3"/>
    <origin xyz="0.0125 0 0.1"/>
    <axis xyz="1 0 0"/>
    <limit effort="300" lower="0" upper="1.57" velocity="0.1"/>
  </joint>
  <link name="link_3">
    <visual>
      <geometry>
        <cylinder length="0.05" radius="0.0125"/>
      </geometry>
      <origin rpy="0 1.57 0" xyz="0 0 0"/>
      <material name="White"/>
    </visual>
  </link>
  <joint name="link_3-link_4" type="fixed">
    <parent link="link_3"/>
    <child link="link_4"/>
    <origin xyz="0 0 0"/>
  </joint>
  <link name="link_4">
    <visual>
      <geometry>
        <box size="0.025 0.025 0.1"/>
      </geometry>
      <origin rpy="0 0 0" xyz="0.0125 0 0.05"/>
      <material name="Black"/>
    </visual>
  </link>
  <joint name="link_4-link_5" type="revolute">
    <parent link="link_4"/>
    <child link="link_5"/>
    <origin xyz="0.0125 0 0.1"/>
    <axis xyz="0 0 1"/>
    <limit effort="300" lower="-1.57" upper="1.57" velocity="0.1"/>
  </joint>
  <link name="link_5">
    <visual>
      <geometry>
        <cylinder length="0.025" radius="0.0125"/>
      </geometry>
      <origin rpy="0 0 0" xyz="0 0 0.0125"/>
      <material name="White"/>
    </visual>
  </link>
  <joint name="link_5-link_6" type="fixed">
    <parent link="link_5"/>
    <child link="link_6"/>
    <origin xyz="0 0 0.025"/>
  </joint>
  <link name="link_6">
    <visual>
      <geometry>
        <box size="0.025 0.025 0.075"/>
      </geometry>
      <origin rpy="0 0 0" xyz="0 0 0.0375"/>
      <material name="Black"/>
    </visual>
  </link>
  <joint name="link_6-link_7" type="revolute">
    <parent link="link_6"/>
    <child link="link_7"/>
    <origin xyz="-0.0125 0 0.075"/>
    <axis xyz="1 0 0"/>
    <limit effort="300" lower="-1.57" upper="1.57" velocity="0.1"/>
  </joint>
  <link name="link_7">
    <visual>
      <geometry>
        <cylinder length="0.05" radius="0.0125"/>
      </geometry>
      <origin rpy="0 1.57 0" xyz="0 0 0"/>
      <material name="White"/>
    </visual>
  </link>
  <joint name="link_7-link_8" type="fixed">
    <parent link="link_7"/>
    <child link="link_8"/>
    <origin xyz="0 0 0"/>
  </joint>
  <link name="link_8">
    <visual>
      <geometry>
        <box size="0.025 0.025 0.05"/>
      </geometry>
      <origin rpy="0 0 0" xyz="-0.0125 0 0.025"/>
      <material name="Black"/>
    </visual>
  </link>
  <joint name="link_8-link_9" type="revolute">
    <parent link="link_8"/>
    <child link="link_9"/>
    <origin xyz="-0.0125 0 0.05"/>
    <axis xyz="0 0 1"/>
    <limit effort="300" lower="-1.57" upper="1.57" velocity="0.1"/>
  </joint>
  <link name="link_9">
    <visual>
      <geometry>
        <cylinder length="0.025" radius="0.0125"/>
      </geometry>
      <origin rpy="0 0 0" xyz="0 0 0.0125"/>
      <material name="White"/>
    </visual>
  </link>
  <joint name="link_9-link_10" type="fixed">
    <parent link="link_9"/>
    <child link="link_10"/>
    <origin xyz="0 0 0.025"/>
  </joint>
  <link name="link_10">
    <visual>
      <geometry>
        <box size="0.025 0.025 0.1"/>
      </geometry>
      <origin rpy="0 0 0" xyz="0 0 0.05"/>
      <material name="Black"/>
    </visual>
  </link>
  <joint name="link_10-link_11" type="revolute">
    <parent link="link_10"/>
    <child link="link_11"/>
    <origin xyz="0.0125 0 0.1"/>
    <axis xyz="1 0 0"/>
    <limit effort="300" lower="-1.57" upper="1.57" velocity="0.1"/>
  </joint>
  <link name="link_11">
    <visual>
      <geometry>
        <cylinder length="0.05" radius="0.0125"/>
      </geometry>
      <origin rpy="0 1.57 0" xyz="0 0 0"/>
      <material name="White"/>
    </visual>
  </link>
  <joint name="link_11-link_12" type="fixed">
    <parent link="link_11"/>
    <child link="link_12"/>
    <origin xyz="0.025 0 0"/>
  </joint>
  <link name="link_12">
    <visual>
      <geometry>
        <sphere radius="0.0125"/>
      </geometry>
      <origin xyz="0 0 0"/>
    </visual>
  </link>
  <joint name="link_12-link_13" type="revolute">
    <parent link="link_12"/>
    <child link="link_13"/>
    <origin xyz="0 0 0"/>
    <axis xyz="0 0 1"/>
    <limit effort="300" lower="-3.14" upper="3.14" velocity="0.1"/>
  </joint>
  <link name="link_13">
    <visual>
      <geometry>
        <cylinder length="0.05" radius="0.0125"/>
      </geometry>
      <origin rpy="0 0 0" xyz="0 0 0.025"/>
      <material name="White"/>
    </visual>
  </link>
  <joint name="link_13-hand" type="fixed">
    <parent link="link_13"/>
    <child link="hand"/>
    <origin xyz="0 0 0.05"/>
  </joint>
  <link name="hand">
    <visual>
      <geometry>
        <box size="0.1 0.025 0.05"/>
      </geometry>
      <origin xyz="0 0 0.025"/>
    </visual>
  </link>
  <joint name="hand-gripper_link_1" type="prismatic">
    <parent link="hand"/>
    <child link="gripper_link_1"/>
    <origin xyz="0.0375 0 0.05"/>
    <axis xyz="1 0 0"/>
    <limit effort="100" lower="0" upper="-0.025" velocity="1.0"/>
  </joint>
  <link name="gripper_link_1">
    <visual>
      <geometry>
        <box size="0.025 0.025 0.05"/>
      </geometry>
      <origin rpy="0 0 0" xyz="0 0 0.025"/>
      <material name="White"/>
    </visual>
  </link>
  <joint name="hand-gripper_link_2" type="prismatic">
    <parent link="hand"/>
    <child link="gripper_link_2"/>
    <origin xyz="-0.0375 0 0.05"/>
    <axis xyz="1 0 0"/>
    <limit effort="100" lower="0" upper="0.025" velocity="1.0"/>
  </joint>
  <link name="gripper_link_2">
    <visual>
      <geometry>
        <box size="0.025 0.025 0.05"/>
      </geometry>
      <origin rpy="0 0 0" xyz="0 0 0.025"/>
      <material name="White"/>
    </visual>
  </link>
</robot>
