<?xml version="1.0"?>
<robot name="my_seven_dof_arm">

<link name="origin">
    <origin xyz="0 0 0.005"/>
</link>

<joint name="rotating_base" type="revolute">
  <parent link="origin"/>
  <child link="base_link"/>
  <origin xyz="0 0 0"/>
  <axis xyz="0 0 1"/>
  <limit effort="300" lower="-3.14" upper="3.14" velocity="0.1"/>
</joint>

  <link name="base_link">
    <visual>
      <geometry>
        <box size="0.4 0.4 0.01"/>
      </geometry>
      <origin xyz="0 0 0.005"/>
    </visual>
  </link>

  <joint name="link_1_pan_joint" type="revolute">
    <parent link="base_link"/>
    <child link="link_1"/>
    <origin xyz="0 0 0.01"/>
    <axis xyz="0 0 1"/>
    <limit effort="300" velocity="0.1" lower="-3.14" upper="3.14"/>
  </joint>

  <link name="link_1">
    <visual>
      <geometry>
        <cylinder length="0.1" radius="0.05"/>
      </geometry>
      <origin xyz="0 0 0.05"/>
    </visual>
  </link>

  <joint name="link_1_link_2_joint" type="revolute">
    <parent link="link_1"/>
    <child link="link_2"/>
    <origin xyz="0 0 0.1"/>
    <limit effort="300" velocity="0.1" lower="1.57" upper="-1.57"/>
  </joint>

  <link name="link_2">
    <visual>
      <geometry>
        <box size="0.025 0.025 0.2"/>
      </geometry>
      <origin xyz="0 0 0.1"/>
    </visual>
  </link>

  <joint name="link_2_link_3_joint" type="revolute">
    <parent link="link_2"/>
    <child link="link_3"/>
    <origin xyz="0 0 0.2"/>
    <limit effort="300" velocity="0.1" lower="1.57" upper="-1.57"/>
    <axis xyz="0 0 1"/>
  </joint>

  <link name="link_3">
    <visual>
      <geometry>
        <cylinder length="0.025" radius="0.0125"/>
      </geometry>
      <origin xyz="0 0 0.0125"/>
    </visual>
  </link>

  <joint name="link_3_link_4_joint" type="revolute">
    <parent link="link_3"/>
    <child link="link_4"/>
    <origin xyz="0 0 0.025"/>
    <limit effort="300" velocity="0.1" lower="0" upper="-1.57"/>
  </joint>

  <link name="link_4">
    <visual>
      <geometry>
        <box size="0.025 0.025 0.025"/>
      </geometry>
      <origin xyz="0 0 0.0125"/>
    </visual>
  </link>

  <joint name="link_4_link_5_joint" type="revolute">
    <parent link="link_4"/>
    <child link="link_5"/>
    <origin xyz="0 0 0.025"/>
    <limit effort="300" velocity="0.1" lower="1.5" upper="-1.57"/>
    <axis xyz="0 0 1"/>
  </joint>

  <link name="link_5">
    <visual>
      <geometry>
        <cylinder length="0.025" radius="0.0125"/>
      </geometry>
      <origin xyz="0 0 0.0125"/>
    </visual>
  </link>

  <joint name="link_5_link_6_joint" type="revolute">
    <parent link="link_5"/>
    <child link="link_6"/>
    <origin xyz="0 0 0.025"/>
    <limit effort="300" velocity="0.1" lower="0" upper="-1.57"/>
  </joint>

  <link name="link_6">
    <visual>
      <geometry>
        <box size="0.025 0.025 0.2"/>
      </geometry>
      <origin xyz="0 0 0.1"/>
    </visual>
  </link>

  <joint name="link_6_link_7_joint" type="revolute">
    <parent link="link_6"/>
    <child link="link_7"/>
    <origin xyz="0 0 0.2"/>
    <limit effort="300" velocity="0.1" lower="1.57" upper="-1.57"/>
    <axis xyz="0 0 1"/>
  </joint>

  <link name="link_7">
    <visual>
      <geometry>
        <cylinder length="0.025" radius="0.0125"/>
      </geometry>
      <origin xyz="0 0 0.0125"/>
    </visual>
  </link>

  <joint name="link_7_link_8_joint" type="revolute">
    <parent link="link_7"/>
    <child link="hand"/>
    <origin xyz="0 0 0.025"/>
    <limit effort="300" velocity="0.1" lower="1.5" upper="-1.57"/>
  </joint>

  <link name="hand">
    <visual>
      <geometry>
        <box size="0.075 0.025 0.05"/>
      </geometry>
      <origin xyz="0 0 0.025"/>
    </visual>
  </link>

</robot>
